[2021-09-15 13:35:16,347] [INFO] [base._load_session] -> No session loaded
[2021-09-15 13:35:16,363] [INFO] [base._start_message] -> 
                 --------------------------------------------------
                 Starting fuzzing session
                 Target: FileTarget
                 UI: WebInterface listening on 127.0.0.1:26001
                 Log: ./kittylogs/kitty_20210915-133515.log

                 Total possible mutation count: 91
                 --------------------------------------------------
                                 Happy hacking
                 --------------------------------------------------
            
[2021-09-15 13:35:16,388] [INFO] [base.start] -> Performing environment test
[2021-09-15 13:35:16,392] [INFO] [base._test_info] -> Current test: -1
[2021-09-15 13:35:16,392] [INFO] [server.transmit] -> request(18): 5468652064656661756c7420737472696e67
[2021-09-15 13:35:16,392] [ERROR] [server.transmit] -> target.transmit - failure in send (exception: 'bytes' object has no attribute 'encode')
[2021-09-15 13:35:16,393] [ERROR] [server.transmit] -> Traceback (most recent call last):
  File "D:\windowsSoftware\Anaconda\envs\Kitty\lib\site-packages\kitty\targets\server.py", line 93, in transmit
    self._send_to_target(payload)
  File "D:\windowsSoftware\Anaconda\envs\Kitty\lib\site-packages\katnip\targets\file.py", line 73, in _send_to_target
    self.logger.debug('data (start): %s', data[:end].encode('hex'))
AttributeError: 'bytes' object has no attribute 'encode'

[2021-09-15 13:35:16,401] [INFO] [server._test_environment] -> Environment test failed
[2021-09-15 13:35:16,401] [ERROR] [base.start] -> Error occurred while fuzzing: Exception('status must be one of: passed, failed, error')
[2021-09-15 13:35:16,407] [ERROR] [base.start] -> Traceback (most recent call last):
  File "D:\windowsSoftware\Anaconda\envs\Kitty\lib\site-packages\kitty\fuzzers\base.py", line 385, in start
    self._test_environment()
  File "D:\windowsSoftware\Anaconda\envs\Kitty\lib\site-packages\kitty\fuzzers\server.py", line 53, in _test_environment
    if self._run_sequence(sequence):
  File "D:\windowsSoftware\Anaconda\envs\Kitty\lib\site-packages\kitty\fuzzers\server.py", line 75, in _run_sequence
    return self._post_test()
  File "D:\windowsSoftware\Anaconda\envs\Kitty\lib\site-packages\kitty\fuzzers\base.py", line 434, in _post_test
    self.target.post_test(self.model.current_index())
  File "D:\windowsSoftware\Anaconda\envs\Kitty\lib\site-packages\kitty\targets\server.py", line 129, in post_test
    super(ServerTarget, self).post_test(test_num)
  File "D:\windowsSoftware\Anaconda\envs\Kitty\lib\site-packages\kitty\targets\base.py", line 97, in post_test
    controller_report = self.controller.get_report()
  File "D:\windowsSoftware\Anaconda\envs\Kitty\lib\site-packages\kitty\remote\actor.py", line 41, in get_report
    report = Report.from_dict(report_dict)
  File "D:\windowsSoftware\Anaconda\envs\Kitty\lib\site-packages\kitty\data\report.py", line 205, in from_dict
    report.set_status(Report._decode(d['status'], encoding))
  File "D:\windowsSoftware\Anaconda\envs\Kitty\lib\site-packages\kitty\data\report.py", line 128, in set_status
    raise Exception('status must be one of: %s' % (', '.join(Report.allowed_statuses)))
Exception: status must be one of: passed, failed, error

