[2022-01-06 16:39:35,397] [INFO] [base._load_session] -> No session loaded
[2022-01-06 16:39:35,401] [INFO] [base._start_message] -> 
                 --------------------------------------------------
                 Starting fuzzing session
                 Target: FileTarget
                 UI: WebInterface listening on 127.0.0.1:26001
                 Log: ./kittylogs/kitty_20220106-163934.log

                 Total possible mutation count: 91
                 --------------------------------------------------
                                 Happy hacking
                 --------------------------------------------------
            
[2022-01-06 16:39:37,415] [ERROR] [base.start] -> Error occurred while fuzzing: ConnectionError(MaxRetryError("HTTPConnectionPool(host='127.0.0.1', port=25002): Max retries exceeded with url: / (Caused by NewConnectionError('<urllib3.connection.HTTPConnection object at 0x000002028D246040>: Failed to establish a new connection: [WinError 10061] 由于目标计算机积极拒绝，无法连接。'))"))
[2022-01-06 16:39:37,419] [ERROR] [base.start] -> Traceback (most recent call last):
  File "D:\windowsSoftware\Anaconda\envs\miio\lib\site-packages\urllib3\connection.py", line 174, in _new_conn
    conn = connection.create_connection(
  File "D:\windowsSoftware\Anaconda\envs\miio\lib\site-packages\urllib3\util\connection.py", line 96, in create_connection
    raise err
  File "D:\windowsSoftware\Anaconda\envs\miio\lib\site-packages\urllib3\util\connection.py", line 86, in create_connection
    sock.connect(sa)
ConnectionRefusedError: [WinError 10061] 由于目标计算机积极拒绝，无法连接。

During handling of the above exception, another exception occurred:

Traceback (most recent call last):
  File "D:\windowsSoftware\Anaconda\envs\miio\lib\site-packages\urllib3\connectionpool.py", line 699, in urlopen
    httplib_response = self._make_request(
  File "D:\windowsSoftware\Anaconda\envs\miio\lib\site-packages\urllib3\connectionpool.py", line 394, in _make_request
    conn.request(method, url, **httplib_request_kw)
  File "D:\windowsSoftware\Anaconda\envs\miio\lib\site-packages\urllib3\connection.py", line 239, in request
    super(HTTPConnection, self).request(method, url, body=body, headers=headers)
  File "D:\windowsSoftware\Anaconda\envs\miio\lib\http\client.py", line 1256, in request
    self._send_request(method, url, body, headers, encode_chunked)
  File "D:\windowsSoftware\Anaconda\envs\miio\lib\http\client.py", line 1302, in _send_request
    self.endheaders(body, encode_chunked=encode_chunked)
  File "D:\windowsSoftware\Anaconda\envs\miio\lib\http\client.py", line 1251, in endheaders
    self._send_output(message_body, encode_chunked=encode_chunked)
  File "D:\windowsSoftware\Anaconda\envs\miio\lib\http\client.py", line 1011, in _send_output
    self.send(msg)
  File "D:\windowsSoftware\Anaconda\envs\miio\lib\http\client.py", line 951, in send
    self.connect()
  File "D:\windowsSoftware\Anaconda\envs\miio\lib\site-packages\urllib3\connection.py", line 205, in connect
    conn = self._new_conn()
  File "D:\windowsSoftware\Anaconda\envs\miio\lib\site-packages\urllib3\connection.py", line 186, in _new_conn
    raise NewConnectionError(
urllib3.exceptions.NewConnectionError: <urllib3.connection.HTTPConnection object at 0x000002028D246040>: Failed to establish a new connection: [WinError 10061] 由于目标计算机积极拒绝，无法连接。

During handling of the above exception, another exception occurred:

Traceback (most recent call last):
  File "D:\windowsSoftware\Anaconda\envs\miio\lib\site-packages\requests\adapters.py", line 439, in send
    resp = conn.urlopen(
  File "D:\windowsSoftware\Anaconda\envs\miio\lib\site-packages\urllib3\connectionpool.py", line 755, in urlopen
    retries = retries.increment(
  File "D:\windowsSoftware\Anaconda\envs\miio\lib\site-packages\urllib3\util\retry.py", line 574, in increment
    raise MaxRetryError(_pool, url, error or ResponseError(cause))
urllib3.exceptions.MaxRetryError: HTTPConnectionPool(host='127.0.0.1', port=25002): Max retries exceeded with url: / (Caused by NewConnectionError('<urllib3.connection.HTTPConnection object at 0x000002028D246040>: Failed to establish a new connection: [WinError 10061] 由于目标计算机积极拒绝，无法连接。'))

During handling of the above exception, another exception occurred:

Traceback (most recent call last):
  File "D:\windowsSoftware\Anaconda\envs\miio\lib\site-packages\kitty\fuzzers\base.py", line 379, in start
    self.target.setup()
  File "D:\windowsSoftware\Anaconda\envs\miio\lib\site-packages\kitty\targets\base.py", line 61, in setup
    self.controller.setup()
  File "D:\windowsSoftware\Anaconda\envs\miio\lib\site-packages\kitty\remote\rpc.py", line 163, in _
    response = requests.post(self.url, data=json.dumps(payload), headers=self.headers).json()
  File "D:\windowsSoftware\Anaconda\envs\miio\lib\site-packages\requests\api.py", line 117, in post
    return request('post', url, data=data, json=json, **kwargs)
  File "D:\windowsSoftware\Anaconda\envs\miio\lib\site-packages\requests\api.py", line 61, in request
    return session.request(method=method, url=url, **kwargs)
  File "D:\windowsSoftware\Anaconda\envs\miio\lib\site-packages\requests\sessions.py", line 542, in request
    resp = self.send(prep, **send_kwargs)
  File "D:\windowsSoftware\Anaconda\envs\miio\lib\site-packages\requests\sessions.py", line 655, in send
    r = adapter.send(request, **kwargs)
  File "D:\windowsSoftware\Anaconda\envs\miio\lib\site-packages\requests\adapters.py", line 516, in send
    raise ConnectionError(e, request=request)
requests.exceptions.ConnectionError: HTTPConnectionPool(host='127.0.0.1', port=25002): Max retries exceeded with url: / (Caused by NewConnectionError('<urllib3.connection.HTTPConnection object at 0x000002028D246040>: Failed to establish a new connection: [WinError 10061] 由于目标计算机积极拒绝，无法连接。'))

