[2022-01-06 13:57:03,400] [INFO] [base._load_session] -> No session loaded
[2022-01-06 13:57:03,402] [INFO] [base._start_message] -> 
                 --------------------------------------------------
                 Starting fuzzing session
                 Target: FileTarget
                 UI: WebInterface listening on 127.0.0.1:26001
                 Log: ./kittylogs/kitty_20220106-135702.log

                 Total possible mutation count: 182
                 --------------------------------------------------
                                 Happy hacking
                 --------------------------------------------------
            
[2022-01-06 13:57:03,404] [INFO] [base.start] -> Performing environment test
[2022-01-06 13:57:03,405] [INFO] [base._test_info] -> Current test: -1
[2022-01-06 13:57:03,405] [INFO] [server.transmit] -> request(32): 5468652064656661756c7420737472696e67416e6f7468657220737472696e67
[2022-01-06 13:57:03,407] [ERROR] [server.transmit] -> target.transmit - failure in send (exception: 'bytes' object has no attribute 'encode')
[2022-01-06 13:57:03,408] [ERROR] [server.transmit] -> Traceback (most recent call last):
  File "D:\windowsSoftware\Anaconda\envs\miio\lib\site-packages\kitty\targets\server.py", line 93, in transmit
    self._send_to_target(payload)
  File "D:\windowsSoftware\Anaconda\envs\miio\lib\site-packages\katnip\targets\file.py", line 73, in _send_to_target
    self.logger.debug('data (start): %s', data[:end].encode('hex'))
AttributeError: 'bytes' object has no attribute 'encode'

[2022-01-06 13:57:03,409] [WARNING] [base.post_test] -> Test -1 status: failed
[2022-01-06 13:57:03,409] [WARNING] [base.post_test] -> Reason: failed to send payload: 'bytes' object has no attribute 'encode'
[2022-01-06 13:57:03,410] [INFO] [server._test_environment] -> Environment test failed
[2022-01-06 13:57:03,410] [ERROR] [base.start] -> Error occurred while fuzzing: Exception('Environment test failed')
[2022-01-06 13:57:03,411] [ERROR] [base.start] -> Traceback (most recent call last):
  File "D:\windowsSoftware\Anaconda\envs\miio\lib\site-packages\kitty\fuzzers\base.py", line 385, in start
    self._test_environment()
  File "D:\windowsSoftware\Anaconda\envs\miio\lib\site-packages\kitty\fuzzers\server.py", line 55, in _test_environment
    raise Exception('Environment test failed')
Exception: Environment test failed

