[2021-12-12 20:18:17,723] [INFO] [base._load_session] -> No session loaded
[2021-12-12 20:18:17,724] [INFO] [base._start_message] -> 
                 --------------------------------------------------
                 Starting fuzzing session
                 Target: TcpTarget
                 UI: WebInterface listening on 127.0.0.1:26001
                 Log: ./kittylogs/kitty_20211212-201816.log

                 Total possible mutation count: 0
                 --------------------------------------------------
                                 Happy hacking
                 --------------------------------------------------
            
[2021-12-12 20:18:17,725] [INFO] [base.start] -> Performing environment test
[2021-12-12 20:18:17,728] [ERROR] [tcp.pre_test] -> Error: Traceback (most recent call last):
  File "D:\windowsSoftware\Anaconda\envs\Kitty\lib\site-packages\katnip\targets\tcp.py", line 57, in pre_test
    sock.connect((self.host, self.port))
socket.gaierror: [Errno 11001] getaddrinfo failed

[2021-12-12 20:18:17,729] [ERROR] [tcp.pre_test] -> Failed to connect to target server, retrying...
[2021-12-12 20:18:18,744] [ERROR] [tcp.pre_test] -> Error: Traceback (most recent call last):
  File "D:\windowsSoftware\Anaconda\envs\Kitty\lib\site-packages\katnip\targets\tcp.py", line 57, in pre_test
    sock.connect((self.host, self.port))
socket.gaierror: [Errno 11001] getaddrinfo failed

[2021-12-12 20:18:18,745] [ERROR] [tcp.pre_test] -> Failed to connect to target server, retrying...
[2021-12-12 20:18:19,747] [ERROR] [tcp.pre_test] -> Error: Traceback (most recent call last):
  File "D:\windowsSoftware\Anaconda\envs\Kitty\lib\site-packages\katnip\targets\tcp.py", line 57, in pre_test
    sock.connect((self.host, self.port))
socket.gaierror: [Errno 11001] getaddrinfo failed

[2021-12-12 20:18:19,750] [ERROR] [tcp.pre_test] -> Failed to connect to target server, retrying...
[2021-12-12 20:18:20,761] [ERROR] [tcp.pre_test] -> Error: Traceback (most recent call last):
  File "D:\windowsSoftware\Anaconda\envs\Kitty\lib\site-packages\katnip\targets\tcp.py", line 57, in pre_test
    sock.connect((self.host, self.port))
socket.gaierror: [Errno 11001] getaddrinfo failed

[2021-12-12 20:18:20,764] [ERROR] [tcp.pre_test] -> Failed to connect to target server, retrying...
